Workbook

Sheet README
A1: Project | B1: Purpose | C1: Records | D1: Recommended Tools | E1: Important Note
A2: HR Workforce Analytics and Interactive Dashboard System | B2: Synthetic project-ready HR dataset for Employee Demographics, Recruitment, Attendance, Leave, Salary, Performance, Attrition and Department-wise Dashboard. | C2: 300 employees; 3600 monthly attendance records; 640 leave records | D2: Excel → MySQL → Power BI; Python/Pandas for optional preprocessing | E2: All names and records are synthetic/fictitious and created for academic/project use.

Sheet Average salary by position
A3: Row Labels | B3: Average of Salary
A4: Accountant | B4: 52466.667
A5: Business Development Executive | B5: 41562.5
A6: Customer Success Executive | B6: 34285.714
A7: Data Analyst | B7: 60800
A8: Digital Marketing Analyst | B8: 49125
A9: Finance Manager | B9: 51571.429
A10: Financial Analyst | B10: 55500
A11: HR Executive | B11: 45750
A12: HR Manager | B12: 44250
A13: Marketing Executive | B13: 47846.154
A14: Marketing Manager | B14: 41000
A15: Operations Executive | B15: 41333.333
... A26: Grand Total | B26: 45356.667

Sheet Average salary by department
A3: Row Labels | B3: Average of Salary
A4: Customer Support | B4: 34875
A5: Finance | B5: 53162.791
A6: HR | B6: 44931.818
A7: IT | B7: 53481.481
A8: Marketing | B8: 46763.158
A9: Operations | B9: 37606.061
A10: Sales | B10: 42562.5
A11: Grand Total | B11: 45356.667

Sheet Average salary and  
A3: Row Labels | B3: Average of Salary
A4: Central | B4: 47133.333
A5: East | B5: 45387.097
A6: North | B6: 43365.079
A7: South | B7: 44410.714
A8: West | B8: 46542.373
A9: Grand Total | B9: 45356.667

Sheet Attendance
A1: Employee_ID | B1: Month | C1: Working_Days | D1: Present_Days | E1: Absent_Days | F1: Late_Days | G1: Attendance_Percentage
A2: 1 | B2: 45931 | C2: 20 | D2: 14 | E2: 6 | F2: 1 | G2: 70
A3: 1 | B3: 45962 | C3: 18 | D3: 11 | E3: 7 | F3: 6 | G3: 61.1
A4: 1 | B4: 45992 | C4: 22 | D4: 19 | E4: 3 | F4: 1 | G4: 86.4
A5: 1 | B5: 46023 | C5: 18 | D5: 12 | E5: 6 | F5: 5 | G5: 66.7
A6: 1 | B6: 46054 | C6: 21 | D6: 15 | E6: 6 | F6: 3 | G6: 71.4
A7: 1 | B7: 46082 | C7: 21 | D7: 16 | E7: 5 | F7: 3 | G7: 76.2
A8: 1 | B8: 46113 | C8: 18 | D8: 18 | E8: 0 | F8: 1 | G8: 100
A9: 1 | B9: 46143 | C9: 20 | D9: 19 | E9: 1 | F9: 1 | G9: 95
A10: 1 | B10: 46174 | C10: 22 | D10: 19 | E10: 3 | F10: 5 | G10: 86.4
A11: 1 | B11: 46204 | C11: 20 | D11: 17 | E11: 3 | F11: 4 | G11: 85
A12: 1 | B12: 46235 | C12: 20 | D12: 13 | E12: 7 | F12: 4 | G12: 65
A13: 1 | B13: 46266 | C13: 19 | D13: 17 | E13: 2 | F13: 2 | G13: 89.5
... A3601: 300 | B3601: 46266 | C3601: 21 | D3601: 16 | E3601: 5 | F3601: 2 | G3601: 76.2

Sheet Sheet1
A3: Row Labels | B3: Sum of Leave_ID
A4: Approved | B4: 126367
A5: Pending | B5: 37073
A6: Rejected | B6: 41680
A7: Grand Total | B7: 205120

Sheet Sheet2
A3: Row Labels | B3: Count of Leave_ID
A4: Annual Leave | B4: 173
A5: Casual Leave | B5: 141
A6: Emergency Leave | B6: 158
A7: Sick Leave | B7: 168
A8: Grand Total | B8: 640

Sheet Sheet3
A3: Row Labels | B3: Sum of Leave_Days
A4: Jan | B4: 138
A5: Feb | B5: 108
A6: Mar | B6: 136
A7: Apr | B7: 186
A8: May | B8: 117
A9: Jun | B9: 99
A10: Jul | B10: 124
A11: Aug | B11: 142
A12: Sep | B12: 121
A13: Oct | B13: 135
A14: Nov | B14: 143
A15: Dec | B15: 127
A16: Grand Total | B16: 1576

Sheet Sheet14
A3: Row Labels | B3: Sum of Leave_Days
A4: Customer Support | B4: 83
A5: Finance | B5: 120
A6: HR | B6: 100
A7: IT | B7: 124
A8: Marketing | B8: 91
A9: Not Found | B9: 839
A10: Operations | B10: 92
A11: Sales | B11: 127
A12: Grand Total | B12: 1576

Sheet Sheet4
A3: Row Labels
A4: Approved
A5: Pending
A6: Rejected
A7: Grand Total

Sheet Sheet15
A3: Row Labels | B3: Sum of Leave_Days
A4: 542 | B4: 4
A5: 463 | B5: 4
A6: 623 | B6: 4
A7: 323 | B7: 4
A8: 507 | B8: 4
A9: 324 | B9: 4
A10: 594 | B10: 4
A11: 327 | B11: 4
A12: 455 | B12: 4
A13: 336 | B13: 4
A14: 488 | B14: 4
A15: 337 | B15: 4
... A643: 276 | B643: 1
A644: Grand Total | B644: 1576

Sheet Sheet20
A3: Row Labels | B3: Sum of Percentage | C3: Count of Leave_Days
A4: 1 | B4: 244.0359 | C4: 4
A5: 2 | B5: 243.58774 | C5: 4
A6: 3 | B6: 182.27828 | C6: 3
A7: 4 | B7: 181.71681 | C7: 3
A8: 5 | B8: 181.6297 | C8: 3
A9: 6 | B9: 121.25108 | C9: 2
A10: 7 | B10: 60.771704 | C10: 1
A11: 8 | B11: 182.41967 | C11: 3
A12: 9 | B12: 183.1443 | C12: 3
A13: 11 | B13: 121.88766 | C13: 2
A14: 12 | B14: 61.011419 | C14: 1
A15: 13 | B15: 122.32224 | C15: 2
... A251: 300 | B251: 50 | C251: 1
A252: Grand Total | B252: 40208.515 | C252: 640

Sheet Sheet22
A1: 1 | B1: 244.0359 | C1: 4
A2: 2 | B2: 243.58774 | C2: 4
A3: 3 | B3: 182.27828 | C3: 3
A4: 4 | B4: 181.71681 | C4: 3
A5: 5 | B5: 181.6297 | C5: 3
A6: 6 | B6: 121.25108 | C6: 2
A7: 7 | B7: 60.771704 | C7: 1
A8: 8 | B8: 182.41967 | C8: 3
A9: 9 | B9: 183.1443 | C9: 3
A10: 11 | B10: 121.88766 | C10: 2
A11: 12 | B11: 61.011419 | C11: 1
A12: 13 | B12: 122.32224 | C12: 2
... A248: 300 | B248: 50 | C248: 1

Sheet Employee_Master
A1: Employee_ID | B1: Employee_Name | C1: Gender | D1: Age | E1: Department | F1: Position | G1: Salary | H1: Hire_Date | I1: Years_of_Service | J1: Recruitment_Source | K1: Performance_Score | L1: Attendance_Percentage | M1: Absence_Days | N1: Leave_Days | O1: Employment_Status | P1: Termination_Date | Q1: Location
A2: 1 | B2: Employee_001 | C2: Male | D2: 38 | E2: Marketing | F2: Marketing Executive | G2: 48000 | H2: 44469 | I2: 5 | J2: Campus Recruitment | K2: 84.1 | L2: 97.6 | M2: 13 | N2: 1 | O2: Active | Q2: North
A3: 2 | B3: Employee_002 | C3: Male | D3: 53 | E3: IT | F3: Data Analyst | G3: 74000 | H3: 45931 | I3: 1 | J3: Indeed | K3: 56.1 | L3: 85.5 | M3: 14 | N3: 18 | O3: Resigned | P3: 45872 | Q3: East
A4: 3 | B4: Employee_003 | C4: Male | D4: 48 | E4: Customer Support | F4: Support Executive | G4: 35000 | H4: 44859 | I4: 4 | J4: LinkedIn | K4: 87.8 | L4: 83.8 | M4: 11 | N4: 11 | O4: Active | Q4: Central
A5: 4 | B5: Employee_004 | C5: Female | D5: 55 | E5: HR | F5: HR Executive | G5: 51000 | H5: 43977 | I5: 6.4 | J5: Naukri | K5: 96.8 | L5: 88.6 | M5: 19 | N5: 11 | O5: Resigned | P5: 46001 | Q5: Central
A6: 5 | B6: Employee_005 | C6: Male | D6: 23 | E6: Sales | F6: Business Development Executive | G6: 43000 | H6: 46174 | I6: 0.4 | J6: Company Website | K6: 58.4 | L6: 86.1 | M6: 8 | N6: 14 | O6: Active | Q6: East
A7: 6 | B7: Employee_006 | C7: Female | D7: 34 | E7: Sales | F7: Sales Manager | G7: 49000 | H7: 46211 | I7: 0.2 | J7: Campus Recruitment | K7: 66.5 | L7: 98.4 | M7: 20 | N7: 5 | O7: Active | Q7: Central
A8: 7 | B8: Employee_007 | C8: Male | D8: 50 | E8: Marketing | F8: Marketing Executive | G8: 43000 | H8: 45020 | I8: 3.5 | J8: LinkedIn | K8: 84.6 | L8: 85.8 | M8: 7 | N8: 1 | O8: Active | Q8: East
A9: 8 | B9: Employee_008 | C9: Male | D9: 34 | E9: Finance | F9: Financial Analyst | G9: 77000 | H9: 45789 | I9: 1.4 | J9: Company Website | K9: 92.7 | L9: 87.5 | M9: 20 | N9: 14 | O9: Active | Q9: South
A10: 9 | B10: Employee_009 | C10: Male | D10: 56 | E10: HR | F10: HR Executive | G10: 43000 | H10: 45673 | I10: 1.7 | J10: Indeed | K10: 93.6 | L10: 89 | M10: 16 | N10: 15 | O10: Active | Q10: North
A11: 10 | B11: Employee_010 | C11: Male | D11: 30 | E11: Customer Support | F11: Support Executive | G11: 46000 | H11: 46036 | I11: 0.7 | J11: Company Website | K11: 61.9 | L11: 93.9 | M11: 12 | N11: 14 | O11: Resigned | P11: 46236 | Q11: Central
A12: 11 | B12: Employee_011 | C12: Male | D12: 28 | E12: HR | F12: Recruiter | G12: 57000 | H12: 46258 | I12: 0.1 | J12: Company Website | K12: 88 | L12: 88 | M12: 5 | N12: 14 | O12: Active | Q12: North | T12: Average Salary | U12: =AVERAGE(G2:G301) -> 45356.667
A13: 12 | B13: Employee_012 | C13: Female | D13: 53 | E13: Marketing | F13: Marketing Manager | G13: 34000 | H13: 44197 | I13: 5.8 | J13: Naukri | K13: 76.8 | L13: 83.9 | M13: 16 | N13: 6 | O13: Active | Q13: South | T13: Median salary | U13: =MEDIAN(G2:G301) -> 44000
A14: 13 | B14: Employee_013 | C14: Male | D14: 41 | E14: HR | F14: HR Executive | G14: 67000 | H14: 45467 | I14: 2.3 | J14: Indeed | K14: 92.8 | L14: 96.6 | M14: 1 | N14: 7 | O14: Active | Q14: Central | T14: Maximum salary | U14: =MAX(G2:G301) -> 77000
A15: 14 | B15: Employee_014 | C15: Female | D15: 25 | E15: IT | F15: Software Developer | G15: 58000 | H15: 45647 | I15: 1.8 | J15: Campus Recruitment | K15: 87.9 | L15: 84.2 | M15: 5 | N15: 8 | O15: Active | Q15: Central | T15: Minimum Salary | U15: =MIN(G2:G301) -> 18000
A16: 15 | B16: Employee_015 | C16: Female | D16: 34 | E16: Customer Support | F16: Customer Success Executive | G16: 36000 | H16: 45674 | I16: 1.7 | J16: Company Website | K16: 85.7 | L16: 89 | M16: 16 | N16: 14 | O16: Active | Q16: North
A17: 16 | B17: Employee_016 | C17: Male | D17: 42 | E17: Sales | F17: Sales Executive | G17: 27000 | H17: 43552 | I17: 7.5 | J17: LinkedIn | K17: 80.3 | L17: 86 | M17: 2 | N17: 1 | O17: Active | Q17: South
A18: 17 | B18: Employee_017 | C18: Female | D18: 25 | E18: IT | F18: Software Developer | G18: 56000 | H18: 45571 | I18: 2 | J18: Company Website | K18: 64.2 | L18: 84.3 | M18: 7 | N18: 15 | O18: Resigned | P18: 45711 | Q18: West
A19: 18 | B19: Employee_018 | C19: Male | D19: 48 | E19: Sales | F19: Sales Executive | G19: 55000 | H19: 44917 | I19: 3.8 | J19: Naukri | K19: 73.2 | L19: 90.2 | M19: 20 | N19: 3 | O19: Active | Q19: North
A20: 19 | B20: Employee_019 | C20: Female | D20: 27 | E20: Finance | F20: Finance Manager | G20: 57000 | H20: 44484 | I20: 5 | J20: Indeed | K20: 61 | L20: 85.2 | M20: 2 | N20: 14 | O20: Active | Q20: Central
A21: 20 | B21: Employee_020 | C21: Male | D21: 26 | E21: IT | F21: Software Developer | G21: 69000 | H21: 44434 | I21: 5.1 | J21: Company Website | K21: 62.2 | L21: 90.5 | M21: 1 | N21: 5 | O21: Active | Q21: West
A22: 21 | B22: Employee_021 | C22: Female | D22: 50 | E22: IT | F22: QA Engineer | G22: 28000 | H22: 44634 | I22: 4.6 | J22: Indeed | K22: 97.8 | L22: 91.7 | M22: 6 | N22: 9 | O22: Active | Q22: South
A23: 22 | B23: Employee_022 | C23: Female | D23: 24 | E23: IT | F23: Software Developer | G23: 69000 | H23: 43671 | I23: 7.2 | J23: LinkedIn | K23: 80.1 | L23: 90.8 | M23: 16 | N23: 2 | O23: Resigned | P23: 46140 | Q23: South
A24: 23 | B24: Employee_023 | C24: Male | D24: 46 | E24: IT | F24: Software Developer | G24: 69000 | H24: 43957 | I24: 6.4 | J24: Company Website | K24: 79.9 | L24: 82.7 | M24: 21 | N24: 18 | O24: Active | Q24: Central
A25: 24 | B25: Employee_024 | C25: Female | D25: 34 | E25: Operations | F25: Operations Manager | G25: 38000 | H25: 46209 | I25: 0.3 | J25: Indeed | K25: 85.8 | L25: 86.2 | M25: 21 | N25: 9 | O25: Active | Q25: West
A26: 25 | B26: Employee_025 | C26: Male | D26: 50 | E26: HR | F26: HR Executive | G26: 77000 | H26: 46010 | I26: 0.8 | J26: Indeed | K26: 58.2 | L26: 85.7 | M26: 11 | N26: 2 | O26: Active | Q26: South
A27: 26 | B27: Employee_026 | C27: Male | D27: 49 | E27: HR | F27: HR Manager | G27: 44000 | H27: 45691 | I27: 1.7 | J27: Naukri | K27: 85.3 | L27: 92.7 | M27: 17 | N27: 9 | O27: Resigned | P27: 46293 | Q27: North
A28: 27 | B28: Employee_027 | C28: Male | D28: 27 | E28: Sales | F28: Sales Manager | G28: 46000 | H28: 45732 | I28: 1.6 | J28: Campus Recruitment | K28: 64.1 | L28: 88 | M28: 15 | N28: 8 | O28: Active | Q28: North
A29: 28 | B29: Employee_028 | C29: Female | D29: 23 | E29: IT | F29: QA Engineer | G29: 63000 | H29: 43480 | I29: 7.7 | J29: Indeed | K29: 69.3 | L29: 84.3 | M29: 23 | N29: 14 | O29: Active | Q29: Central
A30: 29 | B30: Employee_029 | C30: Male | D30: 28 | E30: Marketing | F30: Digital Marketing Analyst | G30: 60000 | H30: 43774 | I30: 6.9 | J30: Campus Recruitment | K30: 61.4 | L30: 82.6 | M30: 17 | N30: 4 | O30: Active | Q30: West
A31: 30 | B31: Employee_030 | C31: Female | D31: 44 | E31: Sales | F31: Sales Executive | G31: 37000 | H31: 43629 | I31: 7.3 | J31: Naukri | K31: 93.7 | L31: 85.7 | M31: 3 | N31: 11 | O31: Active | Q31: Central
A32: 31 | B32: Employee_031 | C32: Male | D32: 36 | E32: Customer Support | F32: Support Lead | G32: 50000 | H32: 44131 | I32: 5.9 | J32: Company Website | K32: 92.9 | L32: 82.4 | M32: 21 | N32: 7 | O32: Active | Q32: East
A33: 32 | B33: Employee_032 | C33: Male | D33: 45 | E33: Sales | F33: Business Development Executive | G33: 39000 | H33: 43624 | I33: 7.3 | J33: Employee Referral | K33: 91.9 | L33: 85.9 | M33: 9 | N33: 7 | O33: Active | Q33: South
A34: 33 | B34: Employee_033 | C34: Female | D34: 42 | E34: IT | F34: Data Analyst | G34: 75000 | H34: 44607 | I34: 4.6 | J34: Naukri | K34: 67 | L34: 93.2 | M34: 17 | N34: 10 | O34: Active | Q34: North
A35: 34 | B35: Employee_034 | C35: Male | D35: 58 | E35: IT | F35: System Administrator | G35: 31000 | H35: 44553 | I35: 4.8 | J35: Naukri | K35: 56.6 | L35: 92.4 | M35: 10 | N35: 13 | O35: Active | Q35: Central
A36: 35 | B36: Employee_035 | C36: Female | D36: 57 | E36: Operations | F36: Operations Executive | G36: 42000 | H36: 44244 | I36: 5.6 | J36: Indeed | K36: 55.1 | L36: 98.2 | M36: 11 | N36: 13 | O36: Resigned | P36: 45615 | Q36: North
A37: 36 | B37: Employee_036 | C37: Female | D37: 28 | E37: Marketing | F37: Digital Marketing Analyst | G37: 61000 | H37: 44696 | I37: 4.4 | J37: Company Website | K37: 76.8 | L37: 93.7 | M37: 22 | N37: 9 | O37: Active | Q37: Central
A38: 37 | B38: Employee_037 | C38: Female | D38: 45 | E38: Sales | F38: Sales Executive | G38: 41000 | H38: 46240 | I38: 0.2 | J38: Employee Referral | K38: 79.5 | L38: 89.1 | M38: 9 | N38: 6 | O38: Active | Q38: West
A39: 38 | B39: Employee_038 | C39: Female | D39: 50 | E39: Customer Support | F39: Customer Success Executive | G39: 31000 | H39: 45275 | I39: 2.8 | J39: Naukri | K39: 74 | L39: 85.7 | M39: 5 | N39: 2 | O39: Active | Q39: East
A40: 39 | B40: Employee_039 | C40: Female | D40: 26 | E40: Operations | F40: Process Analyst | G40: 39000 | H40: 44428 | I40: 5.1 | J40: Company Website | K40: 63.6 | L40: 82.4 | M40: 19 | N40: 2 | O40: Active | Q40: West
...

Sheet Leave Status Analysis
A3: Row Labels | B3: Count of Leave_ID
A4: Approved | B4: 391
A5: Pending | B5: 119
A6: Rejected | B6: 130
A7: Grand Total | B7: 640

Sheet Leave
A1: Leave_ID | B1: Employee_ID | C1: Leave_Date | D1: Leave_Type | E1: Leave_Days | F1: Department | G1: Status | H1: Average | I1: Percentage
A2: 1 | B2: 1 | C2: 46185 | D2: Sick Leave | E2: 4 | F2: =_xlfn.XLOOKUP(B2,Employee_Master!A:A,Employee_Master!E:E,"Not Found") -> Marketing | G2: Approved | H2: =AVERAGE(E2:E641) -> 2.4625 | I2: =COUNTIF(G1:G640,"Approved")/COUNTA(G1:G640)*100 -> 60.9375
A3: 2 | B3: 1 | C3: 46066 | D3: Emergency Leave | E3: 3 | F3: =_xlfn.XLOOKUP(B3,Employee_Master!A:A,Employee_Master!E:E,"Not Found") -> Marketing | G3: Approved | H3: =AVERAGE(E3:E642) -> 2.4600939 | I3: =COUNTIF(G2:G641,"Approved")/COUNTA(G2:G641)*100 -> 61.09375
A4: 3 | B4: 1 | C4: 46155 | D4: Annual Leave | E4: 2 | F4: =_xlfn.XLOOKUP(B4,Employee_Master!A:A,Employee_Master!E:E,"Not Found") -> Marketing | G4: Approved | H4: =AVERAGE(E4:E643) -> 2.4592476 | I4: =COUNTIF(G3:G642,"Approved")/COUNTA(G3:G642)*100 -> 61.032864
A5: 4 | B5: 1 | C5: 46096 | D5: Casual Leave | E5: 1 | F5: =_xlfn.XLOOKUP(B5,Employee_Master!A:A,Employee_Master!E:E,"Not Found") -> Marketing | G5: Approved | H5: =AVERAGE(E5:E644) -> 2.4599686 | I5: =COUNTIF(G4:G643,"Approved")/COUNTA(G4:G643)*100 -> 60.971787
A6: 5 | B6: 2 | C6: 46089 | D6: Annual Leave | E6: 2 | F6: =_xlfn.XLOOKUP(B6,Employee_Master!A:A,Employee_Master!E:E,"Not Found") -> IT | G6: Rejected | H6: =AVERAGE(E6:E645) -> 2.4622642 | I6: =COUNTIF(G5:G644,"Approved")/COUNTA(G5:G644)*100 -> 60.910518
A7: 6 | B7: 2 | C7: 46247 | D7: Casual Leave | E7: 2 | F7: =_xlfn.XLOOKUP(B7,Employee_Master!A:A,Employee_Master!E:E,"Not Found") -> IT | G7: Approved | H7: =AVERAGE(E7:E646) -> 2.4629921 | I7: =COUNTIF(G6:G645,"Approved")/COUNTA(G6:G645)*100 -> 60.849057
A8: 7 | B8: 2 | C8: 45977 | D8: Emergency Leave | E8: 3 | F8: =_xlfn.XLOOKUP(B8,Employee_Master!A:A,Employee_Master!E:E,"Not Found") -> IT | G8: Approved | H8: =AVERAGE(E8:E647) -> 2.4637224 | I8: =COUNTIF(G7:G646,"Approved")/COUNTA(G7:G646)*100 -> 60.944882
A9: 8 | B9: 2 | C9: 46105 | D9: Annual Leave | E9: 4 | F9: =_xlfn.XLOOKUP(B9,Employee_Master!A:A,Employee_Master!E:E,"Not Found") -> IT | G9: Approved | H9: =AVERAGE(E9:E648) -> 2.4628752 | I9: =COUNTIF(G8:G647,"Approved")/COUNTA(G8:G647)*100 -> 60.883281
A10: 9 | B10: 3 | C10: 45984 | D10: Annual Leave | E10: 1 | F10: =_xlfn.XLOOKUP(B10,Employee_Master!A:A,Employee_Master!E:E,"Not Found") -> Customer Support | G10: Approved | H10: =AVERAGE(E10:E649) -> 2.460443 | I10: =COUNTIF(G9:G648,"Approved")/COUNTA(G9:G648)*100 -> 60.821485
A11: 10 | B11: 3 | C11: 46046 | D11: Emergency Leave | E11: 1 | F11: =_xlfn.XLOOKUP(B11,Employee_Master!A:A,Employee_Master!E:E,"Not Found") -> Customer Support | G11: Approved | H11: =AVERAGE(E11:E650) -> 2.4627575 | I11: =COUNTIF(G10:G649,"Approved")/COUNTA(G10:G649)*100 -> 60.759494
A12: 11 | B12: 3 | C12: 46211 | D12: Sick Leave | E12: 3 | F12: =_xlfn.XLOOKUP(B12,Employee_Master!A:A,Employee_Master!E:E,"Not Found") -> Customer Support | G12: Approved | H12: =AVERAGE(E12:E651) -> 2.4650794 | I12: =COUNTIF(G11:G650,"Approved")/COUNTA(G11:G650)*100 -> 60.697306
A13: 12 | B13: 4 | C13: 46045 | D13: Sick Leave | E13: 2 | F13: =_xlfn.XLOOKUP(B13,Employee_Master!A:A,Employee_Master!E:E,"Not Found") -> HR | G13: Approved | H13: =AVERAGE(E13:E652) -> 2.4642289 | I13: =COUNTIF(G12:G651,"Approved")/COUNTA(G12:G651)*100 -> 60.634921
... A619: 618 | B619: 293 | C619: 46172 | D619: Sick Leave | E619: 2 | F619: =_xlfn.XLOOKUP(B619,Employee_Master!A:A,Employee_Master!E:E,"Not Found") -> Marketing | G619: Approved | H619: =AVERAGE(E619:E1258) -> 2.173913 | I619: =COUNTIF(G618:G1257,"Approved")/COUNTA(G618:G1257)*100 -> 75
A620: 619 | B620: 293 | C620: 45954 | D620: Annual Leave | E620: 3 | F620: =_xlfn.XLOOKUP(B620,Employee_Master!A:A,Employee_Master!E:E,"Not Found") -> Marketing | G620: Rejected | H620: =AVERAGE(E620:E1259) -> 2.1818182 | I620: =COUNTIF(G619:G1258,"Approved")/COUNTA(G619:G1258)*100 -> 73.913043 | K620: Column1 | L620: Column2
A621: 620 | B621: 293 | C621: 46054 | D621: Annual Leave | E621: 4 | F621: =_xlfn.XLOOKUP(B621,Employee_Master!A:A,Employee_Master!E:E,"Not Found") -> Marketing | G621: Approved | H621: =AVERAGE(E621:E1260) -> 2.1428571 | I621: =COUNTIF(G620:G1259,"Approved")/COUNTA(G620:G1259)*100 -> 72.727273 | K621: LEAVE REQUESTS | L621: =COUNTA(A2:A641) -> 640
A622: 621 | B622: 294 | C622: 46218 | D622: Casual Leave | E622: 1 | F622: =_xlfn.XLOOKUP(B622,Employee_Master!A:A,Employee_Master!E:E,"Not Found") -> HR | G622: Approved | H622: =AVERAGE(E622:E1261) -> 2.05 | I622: =COUNTIF(G621:G1260,"Approved")/COUNTA(G621:G1260)*100 -> 76.190476 | K622: LEAVE DAYS | L622: =SUM(E2:E641) -> 1576
A623: 622 | B623: 294 | C623: 46220 | D623: Sick Leave | E623: 2 | F623: =_xlfn.XLOOKUP(B623,Employee_Master!A:A,Employee_Master!E:E,"Not Found") -> HR | G623: Rejected | H623: =AVERAGE(E623:E1262) -> 2.1052632 | I623: =COUNTIF(G622:G1261,"Approved")/COUNTA(G622:G1261)*100 -> 75
A624: 623 | B624: 294 | C624: 45953 | D624: Sick Leave | E624: 4 | F624: =_xlfn.XLOOKUP(B624,Employee_Master!A:A,Employee_Master!E:E,"Not Found") -> HR | G624: Rejected | H624: =AVERAGE(E624:E1263) -> 2.1111111 | I624: =COUNTIF(G623:G1262,"Approved")/COUNTA(G623:G1262)*100 -> 73.684211
A625: 624 | B625: 295 | C625: 45968 | D625: Casual Leave | E625: 4 | F625: =_xlfn.XLOOKUP(B625,Employee_Master!A:A,Employee_Master!E:E,"Not Found") -> Finance | G625: Approved | H625: =AVERAGE(E625:E1264) -> 2 | I625: =COUNTIF(G624:G1263,"Approved")/COUNTA(G624:G1263)*100 -> 77.777778
A626: 625 | B626: 295 | C626: 46044 | D626: Sick Leave | E626: 2 | F626: =_xlfn.XLOOKUP(B626,Employee_Master!A:A,Employee_Master!E:E,"Not Found") -> Finance | G626: Approved | H626: =AVERAGE(E626:E1265) -> 1.875 | I626: =COUNTIF(G625:G1264,"Approved")/COUNTA(G625:G1264)*100 -> 82.352941
A627: 626 | B627: 295 | C627: 45980 | D627: Casual Leave | E627: 3 | F627: =_xlfn.XLOOKUP(B627,Employee_Master!A:A,Employee_Master!E:E,"Not Found") -> Finance | G627: Approved | H627: =AVERAGE(E627:E1266) -> 1.8666667 | I627: =COUNTIF(G626:G1265,"Approved")/COUNTA(G626:G1265)*100 -> 81.25
A628: 627 | B628: 295 | C628: 46231 | D628: Emergency Leave | E628: 1 | F628: =_xlfn.XLOOKUP(B628,Employee_Master!A:A,Employee_Master!E:E,"Not Found") -> Finance | G628: Approved | H628: =AVERAGE(E628:E1267) -> 1.7857143 | I628: =COUNTIF(G627:G1266,"Approved")/COUNTA(G627:G1266)*100 -> 80
A629: 628 | B629: 296 | C629: 46161 | D629: Sick Leave | E629: 1 | F629: =_xlfn.XLOOKUP(B629,Employee_Master!A:A,Employee_Master!E:E,"Not Found") -> Finance | G629: Approved | H629: =AVERAGE(E629:E1268) -> 1.8461538 | I629: =COUNTIF(G628:G1267,"Approved")/COUNTA(G628:G1267)*100 -> 78.571429
A630: 629 | B630: 296 | C630: 46052 | D630: Casual Leave | E630: 1 | F630: =_xlfn.XLOOKUP(B630,Employee_Master!A:A,Employee_Master!E:E,"Not Found") -> Finance | G630: Approved | H630: =AVERAGE(E630:E1269) -> 1.9166667 | I630: =COUNTIF(G629:G1268,"Approved")/COUNTA(G629:G1268)*100 -> 76.923077
A631: 630 | B631: 296 | C631: 46237 | D631: Sick Leave | E631: 1 | F631: =_xlfn.XLOOKUP(B631,Employee_Master!A:A,Employee_Master!E:E,"Not Found") -> Finance | G631: Rejected | H631: =AVERAGE(E631:E1270) -> 2 | I631: =COUNTIF(G630:G1269,"Approved")/COUNTA(G630:G1269)*100 -> 75
A632: 631 | B632: 296 | C632: 46283 | D632: Annual Leave | E632: 2 | F632: =_xlfn.XLOOKUP(B632,Employee_Master!A:A,Employee_Master!E:E,"Not Found") -> Finance | G632: Approved | H632: =AVERAGE(E632:E1271) -> 2.1 | I632: =COUNTIF(G631:G1270,"Approved")/COUNTA(G631:G1270)*100 -> 72.727273
A633: 632 | B633: 297 | C633: 46041 | D633: Emergency Leave | E633: 3 | F633: =_xlfn.XLOOKUP(B633,Employee_Master!A:A,Employee_Master!E:E,"Not Found") -> IT | G633: Approved | H633: =AVERAGE(E633:E1272) -> 2.1111111 | I633: =COUNTIF(G632:G1271,"Approved")/COUNTA(G632:G1271)*100 -> 80
A634: 633 | B634: 297 | C634: 45976 | D634: Sick Leave | E634: 3 | F634: =_xlfn.XLOOKUP(B634,Employee_Master!A:A,Employee_Master!E:E,"Not Found") -> IT | G634: Approved | H634: =AVERAGE(E634:E1273) -> 2 | I634: =COUNTIF(G633:G1272,"Approved")/COUNTA(G633:G1272)*100 -> 77.777778
... A641: 640 | B641: 300 | C641: 46247 | D641: Sick Leave | E641: 1 | F641: =_xlfn.XLOOKUP(B641,Employee_Master!A:A,Employee_Master!E:E,"Not Found") -> Marketing | G641: Approved | H641: =AVERAGE(E641:E1280) -> 1 | I641: =COUNTIF(G640:G1279,"Approved")/COUNTA(G640:G1279)*100 -> 50

Sheet leave 2
A1: Leave_ID | B1: Employee_ID | C1: Leave_Date | D1: Leave_Type | E1: Leave_Days | F1: Department | G1: Status | H1: Average | I1: Percentage
A2: 1 | B2: 1 | C2: 46185 | D2: Sick Leave | E2: 4 | F2: =_xlfn.XLOOKUP(B2,Employee_Master!A:A,Employee_Master!E:E,"Not Found") -> Marketing | G2: Approved | H2: =AVERAGE(E2:E641) -> 2.4625 | I2: =COUNTIF(G1:G640,"Approved")/COUNTA(G1:G640)*100 -> 60.9375
A3: 2 | B3: 1 | C3: 46066 | D3: Emergency Leave | E3: 3 | F3: =_xlfn.XLOOKUP(B3,Employee_Master!A:A,Employee_Master!E:E,"Not Found") -> Marketing | G3: Approved | H3: =AVERAGE(E3:E642) -> 2.4600939 | I3: =COUNTIF(G2:G641,"Approved")/COUNTA(G2:G641)*100 -> 61.09375
A4: 3 | B4: 1 | C4: 46155 | D4: Annual Leave | E4: 2 | F4: =_xlfn.XLOOKUP(B4,Employee_Master!A:A,Employee_Master!E:E,"Not Found") -> Marketing | G4: Approved | H4: =AVERAGE(E4:E643) -> 2.4592476 | I4: =COUNTIF(G3:G642,"Approved")/COUNTA(G3:G642)*100 -> 61.032864
A5: 4 | B5: 1 | C5: 46096 | D5: Casual Leave | E5: 1 | F5: =_xlfn.XLOOKUP(B5,Employee_Master!A:A,Employee_Master!E:E,"Not Found") -> Marketing | G5: Approved | H5: =AVERAGE(E5:E644) -> 2.4599686 | I5: =COUNTIF(G4:G643,"Approved")/COUNTA(G4:G643)*100 -> 60.971787
A6: 5 | B6: 2 | C6: 46089 | D6: Annual Leave | E6: 2 | F6: =_xlfn.XLOOKUP(B6,Employee_Master!A:A,Employee_Master!E:E,"Not Found") -> IT | G6: Rejected | H6: =AVERAGE(E6:E645) -> 2.4622642 | I6: =COUNTIF(G5:G644,"Approved")/COUNTA(G5:G644)*100 -> 60.910518
A7: 6 | B7: 2 | C7: 46247 | D7: Casual Leave | E7: 2 | F7: =_xlfn.XLOOKUP(B7,Employee_Master!A:A,Employee_Master!E:E,"Not Found") -> IT | G7: Approved | H7: =AVERAGE(E7:E646) -> 2.4629921 | I7: =COUNTIF(G6:G645,"Approved")/COUNTA(G6:G645)*100 -> 60.849057
A8: 7 | B8: 2 | C8: 45977 | D8: Emergency Leave | E8: 3 | F8: =_xlfn.XLOOKUP(B8,Employee_Master!A:A,Employee_Master!E:E,"Not Found") -> IT | G8: Approved | H8: =AVERAGE(E8:E647) -> 2.4637224 | I8: =COUNTIF(G7:G646,"Approved")/COUNTA(G7:G646)*100 -> 60.944882
A9: 8 | B9: 2 | C9: 46105 | D9: Annual Leave | E9: 4 | F9: =_xlfn.XLOOKUP(B9,Employee_Master!A:A,Employee_Master!E:E,"Not Found") -> IT | G9: Approved | H9: =AVERAGE(E9:E648) -> 2.4628752 | I9: =COUNTIF(G8:G647,"Approved")/COUNTA(G8:G647)*100 -> 60.883281
A10: 9 | B10: 3 | C10: 45984 | D10: Annual Leave | E10: 1 | F10: =_xlfn.XLOOKUP(B10,Employee_Master!A:A,Employee_Master!E:E,"Not Found") -> Customer Support | G10: Approved | H10: =AVERAGE(E10:E649) -> 2.460443 | I10: =COUNTIF(G9:G648,"Approved")/COUNTA(G9:G648)*100 -> 60.821485
A11: 10 | B11: 3 | C11: 46046 | D11: Emergency Leave | E11: 1 | F11: =_xlfn.XLOOKUP(B11,Employee_Master!A:A,Employee_Master!E:E,"Not Found") -> Customer Support | G11: Approved | H11: =AVERAGE(E11:E650) -> 2.4627575 | I11: =COUNTIF(G10:G649,"Approved")/COUNTA(G10:G649)*100 -> 60.759494 | N11: =COUNTA(A2:A641) -> 640
A12: 11 | B12: 3 | C12: 46211 | D12: Sick Leave | E12: 3 | F12: =_xlfn.XLOOKUP(B12,Employee_Master!A:A,Employee_Master!E:E,"Not Found") -> Customer Support | G12: Approved | H12: =AVERAGE(E12:E651) -> 2.4650794 | I12: =COUNTIF(G11:G650,"Approved")/COUNTA(G11:G650)*100 -> 60.697306 | N12: =SUM(E2:E641) -> 1576
A13: 12 | B13: 4 | C13: 46045 | D13: Sick Leave | E13: 2 | F13: =_xlfn.XLOOKUP(B13,Employee_Master!A:A,Employee_Master!E:E,"Not Found") -> HR | G13: Approved | H13: =AVERAGE(E13:E652) -> 2.4642289 | I13: =COUNTIF(G12:G651,"Approved")/COUNTA(G12:G651)*100 -> 60.634921
A14: 13 | B14: 4 | C14: 46156 | D14: Sick Leave | E14: 2 | F14: =_xlfn.XLOOKUP(B14,Employee_Master!A:A,Employee_Master!E:E,"Not Found") -> HR | G14: Approved | H14: =AVERAGE(E14:E653) -> 2.4649682 | I14: =COUNTIF(G13:G652,"Approved")/COUNTA(G13:G652)*100 -> 60.572337
A15: 14 | B15: 4 | C15: 46082 | D15: Sick Leave | E15: 1 | F15: =_xlfn.XLOOKUP(B15,Employee_Master!A:A,Employee_Master!E:E,"Not Found") -> HR | G15: Pending | H15: =AVERAGE(E15:E654) -> 2.4657097 | I15: =COUNTIF(G14:G653,"Approved")/COUNTA(G14:G653)*100 -> 60.509554
A16: 15 | B16: 5 | C16: 46155 | D16: Emergency Leave | E16: 2 | F16: =_xlfn.XLOOKUP(B16,Employee_Master!A:A,Employee_Master!E:E,"Not Found") -> Sales | G16: Rejected | H16: =AVERAGE(E16:E655) -> 2.4680511 | I16: =COUNTIF(G15:G654,"Approved")/COUNTA(G15:G654)*100 -> 60.446571
A17: 16 | B17: 5 | C17: 46026 | D17: Emergency Leave | E17: 4 | F17: =_xlfn.XLOOKUP(B17,Employee_Master!A:A,Employee_Master!E:E,"Not Found") -> Sales | G17: Approved | H17: =AVERAGE(E17:E656) -> 2.4688 | I17: =COUNTIF(G16:G655,"Approved")/COUNTA(G16:G655)*100 -> 60.543131
A18: 17 | B18: 5 | C18: 46292 | D18: Annual Leave | E18: 3 | F18: =_xlfn.XLOOKUP(B18,Employee_Master!A:A,Employee_Master!E:E,"Not Found") -> Sales | G18: Rejected | H18: =AVERAGE(E18:E657) -> 2.4663462 | I18: =COUNTIF(G17:G656,"Approved")/COUNTA(G17:G656)*100 -> 60.64
A19: 18 | B19: 6 | C19: 46117 | D19: Sick Leave | E19: 3 | F19: =_xlfn.XLOOKUP(B19,Employee_Master!A:A,Employee_Master!E:E,"Not Found") -> Sales | G19: Pending | H19: =AVERAGE(E19:E658) -> 2.4654896 | I19: =COUNTIF(G18:G657,"Approved")/COUNTA(G18:G657)*100 -> 60.576923
A20: 19 | B20: 6 | C20: 46113 | D20: Casual Leave | E20: 2 | F20: =_xlfn.XLOOKUP(B20,Employee_Master!A:A,Employee_Master!E:E,"Not Found") -> Sales | G20: Approved | H20: =AVERAGE(E20:E659) -> 2.4646302 | I20: =COUNTIF(G19:G658,"Approved")/COUNTA(G19:G658)*100 -> 60.674157
A21: 20 | B21: 7 | C21: 46206 | D21: Sick Leave | E21: 1 | F21: =_xlfn.XLOOKUP(B21,Employee_Master!A:A,Employee_Master!E:E,"Not Found") -> Marketing | G21: Pending | H21: =AVERAGE(E21:E660) -> 2.4653784 | I21: =COUNTIF(G20:G659,"Approved")/COUNTA(G20:G659)*100 -> 60.771704
A22: 21 | B22: 8 | C22: 46205 | D22: Annual Leave | E22: 1 | F22: =_xlfn.XLOOKUP(B22,Employee_Master!A:A,Employee_Master!E:E,"Not Found") -> Finance | G22: Pending | H22: =AVERAGE(E22:E661) -> 2.4677419 | I22: =COUNTIF(G21:G660,"Approved")/COUNTA(G21:G660)*100 -> 60.708535
A23: 22 | B23: 8 | C23: 46047 | D23: Annual Leave | E23: 2 | F23: =_xlfn.XLOOKUP(B23,Employee_Master!A:A,Employee_Master!E:E,"Not Found") -> Finance | G23: Rejected | H23: =AVERAGE(E23:E662) -> 2.4701131 | I23: =COUNTIF(G22:G661,"Approved")/COUNTA(G22:G661)*100 -> 60.806452
A24: 23 | B24: 8 | C24: 46068 | D24: Casual Leave | E24: 4 | F24: =_xlfn.XLOOKUP(B24,Employee_Master!A:A,Employee_Master!E:E,"Not Found") -> Finance | G24: Pending | H24: =AVERAGE(E24:E663) -> 2.4708738 | I24: =COUNTIF(G23:G662,"Approved")/COUNTA(G23:G662)*100 -> 60.904685
... A641: 640 | B641: 300 | C641: 46247 | D641: Sick Leave | E641: 1 | F641: =_xlfn.XLOOKUP(B641,Employee_Master!A:A,Employee_Master!E:E,"Not Found") -> Marketing | G641: Approved | H641: =AVERAGE(E641:E1280) -> 1 | I641: =COUNTIF(G640:G1279,"Approved")/COUNTA(G640:G1279)*100 -> 50

Sheet table 5
A1: Employee_ID | B1: Leave_Date | C1: Leave_Type | D1: Leave_Days | E1: Department | F1: Status
A2: 1 | B2: 46185 | C2: Sick Leave | D2: 4 | E2: =_xlfn.XLOOKUP(A2,Employee_Master!A:A,Employee_Master!E:E,"Not Found") -> Marketing | F2: Approved
A3: 2 | B3: 46066 | C3: Emergency Leave | D3: 3 | E3: =_xlfn.XLOOKUP(A3,Employee_Master!A:A,Employee_Master!E:E,"Not Found") -> IT | F3: Approved
A4: 3 | B4: 46155 | C4: Annual Leave | D4: 2 | E4: =_xlfn.XLOOKUP(A4,Employee_Master!A:A,Employee_Master!E:E,"Not Found") -> Customer Support | F4: Approved
A5: 4 | B5: 46096 | C5: Casual Leave | D5: 1 | E5: =_xlfn.XLOOKUP(A5,Employee_Master!A:A,Employee_Master!E:E,"Not Found") -> HR | F5: Approved
A6: 5 | B6: 46089 | C6: Annual Leave | D6: 2 | E6: =_xlfn.XLOOKUP(A6,Employee_Master!A:A,Employee_Master!E:E,"Not Found") -> Sales | F6: Rejected
A7: 6 | B7: 46247 | C7: Casual Leave | D7: 2 | E7: =_xlfn.XLOOKUP(A7,Employee_Master!A:A,Employee_Master!E:E,"Not Found") -> Sales | F7: Approved
A8: 7 | B8: 45977 | C8: Emergency Leave | D8: 3 | E8: =_xlfn.XLOOKUP(A8,Employee_Master!A:A,Employee_Master!E:E,"Not Found") -> Marketing | F8: Approved
A9: 8 | B9: 46105 | C9: Annual Leave | D9: 4 | E9: =_xlfn.XLOOKUP(A9,Employee_Master!A:A,Employee_Master!E:E,"Not Found") -> Finance | F9: Approved
A10: 9 | B10: 45984 | C10: Annual Leave | D10: 1 | E10: =_xlfn.XLOOKUP(A10,Employee_Master!A:A,Employee_Master!E:E,"Not Found") -> HR | F10: Approved
A11: 10 | B11: 46046 | C11: Emergency Leave | D11: 1 | E11: =_xlfn.XLOOKUP(A11,Employee_Master!A:A,Employee_Master!E:E,"Not Found") -> Customer Support | F11: Approved
A12: 11 | B12: 46211 | C12: Sick Leave | D12: 3 | E12: =_xlfn.XLOOKUP(A12,Employee_Master!A:A,Employee_Master!E:E,"Not Found") -> HR | F12: Approved
A13: 12 | B13: 46045 | C13: Sick Leave | D13: 2 | E13: =_xlfn.XLOOKUP(A13,Employee_Master!A:A,Employee_Master!E:E,"Not Found") -> Marketing | F13: Approved
... A641: 640 | B641: 46247 | C641: Sick Leave | D641: 1 | E641: =_xlfn.XLOOKUP(A641,Employee_Master!A:A,Employee_Master!E:E,"Not Found") -> Not Found | F641: Approved

Sheet Recruitment_Summary
A1: Recruitment_Source | B1: Total_Hires | C1: Average_Performance | D1: Average_Salary
A2: Campus Recruitment | B2: 59 | C2: 75.42 | D2: 45136
A3: Company Website | B3: 47 | C3: 75.93 | D3: 47043
A4: Employee Referral | B4: 50 | C4: 74.25 | D4: 46460
A5: Indeed | B5: 49 | C5: 74.55 | D5: 46469
A6: LinkedIn | B6: 45 | C6: 78.79 | D6: 43178
A7: Naukri | B7: 50 | C7: 75.69 | D7: 43800

Sheet dashboard of salary
F3: EMPLOYEE COMPENSATION & SALARY ANALYTICS

Sheet dashboard of leave
B2: EMPLOYEE LEAVE ANALYTICS
